Workbook

Sheet Delivery Board
A1: SportIQ — Delivery Board & Roadmap
A2: Delivered dates are REAL (git history, first commit 2026-07-28). Dates from 2026-08-05 onward are PROPOSED. Updated 2026-08-04.
A4: Epic | B4: Feature / Deliverable | C4: Status | D4: Stream | E4: Start | F4: End | G4: Notes | H4: 27 Jul | I4: 03 Aug | J4: 10 Aug | K4: 17 Aug | L4: 24 Aug | M4: 31 Aug | N4: 07 Sep | O4: 14 Sep | P4: 21 Sep | Q4: 28 Sep | R4: EpicKey (helper)
A5: E1 Foundation | B5: PRD/TDD, repo, CLAUDE.md guidance | C5: Done | D5: Platform | E5: 46231 | F5: 46231 | G5: First commit | R5: =IF($A5<>"",$A5,R4) -> E1 Foundation
B6: FastAPI scaffold, TDD §2.1 schema, Alembic | C6: Done | D6: Platform | E6: 46231 | F6: 46232 | G6: All core tables | R6: =IF($A6<>"",$A6,R5) -> E1 Foundation
B7: Docker Compose (Postgres 16 + Redis 7) | C7: Done | D7: Platform | E7: 46231 | F7: 46231 | G7: Local dev only | R7: =IF($A7<>"",$A7,R6) -> E1 Foundation
B8: CI: pytest, ruff, black, tsc | C8: Done | D8: Platform | E8: 46233 | F8: 46233 | G8: GitHub Actions, green | R8: =IF($A8<>"",$A8,R7) -> E1 Foundation
A9: E2 Ingestion | B9: BallDontLie adapter (NBA) | C9: Done | D9: Data | E9: 46231 | F9: 46231 | G9: First real adapter | R9: =IF($A9<>"",$A9,R8) -> E2 Ingestion
B10: TheRundown adapter (odds) | C10: Done | D10: Data | E10: 46232 | F10: 46232 | G10: American->decimal | R10: =IF($A10<>"",$A10,R9) -> E2 Ingestion
B11: API-Football adapter (Pro tier) | C11: Done | D11: Data | E11: 46232 | F11: 46233 | G11: Fixtures/stats/injuries/H2H | R11: =IF($A11<>"",$A11,R10) -> E2 Ingestion
B12: Live scores + outcome settlement | C12: Done | D12: Data | E12: 46233 | F12: 46234 | G12: FixtureLiveState now written | R12: =IF($A12<>"",$A12,R11) -> E2 Ingestion
B13: Celery worker + beat actually running | C13: Done | D13: Data | E13: 46236 | F13: 46237 | G13: Never ran before this | R13: =IF($A13<>"",$A13,R12) -> E2 Ingestion
A14: E3 ML NBA | B14: Historical collection (6 seasons) | C14: Done | D14: ML | E14: 46231 | F14: 46232 | G14: ~14.5k games | R14: =IF($A14<>"",$A14,R13) -> E3 ML NBA
B15: XGBoost + isotonic, 16 features | C15: Done | D15: ML | E15: 46232 | F15: 46232 | G15: 68.57% vs 55.43% base | R15: =IF($A15<>"",$A15,R14) -> E3 ML NBA
B16: Big3/Top5 key-player availability | C16: Done | D16: ML | E16: 46232 | F16: 46233 | G16: Two-stage, leakage-guarded | R16: =IF($A16<>"",$A16,R15) -> E3 ML NBA
A17: E4 ML Football | B17: EPL + Brasileirao collection | C17: Done | D17: ML | E17: 46232 | F17: 46233 | G17: 7.6k game-log rows | R17: =IF($A17<>"",$A17,R16) -> E4 ML Football
B18: Two-layer Poisson -> XGBoost 1X2 | C18: Done | D18: ML | E18: 46233 | F18: 46233 | G18: 47.9% vs 46.5% base | R18: =IF($A18<>"",$A18,R17) -> E4 ML Football
B19: Elo, streaks, richer H2H | C19: Done | D19: ML | E19: 46233 | F19: 46233 | G19: 21 features | R19: =IF($A19<>"",$A19,R18) -> E4 ML Football
B20: Expand to 5 leagues (MLS/CSL/Scot) | C20: Done | D20: ML | E20: 46236 | F20: 46236 | G20: Fixed O/U bias | R20: =IF($A20<>"",$A20,R19) -> E4 ML Football
B21: Retrodiction for completed fixtures | C21: Done | D21: ML | E21: 46234 | F21: 46234 | G21: Leakage-safe path | R21: =IF($A21<>"",$A21,R20) -> E4 ML Football
A22: E5 ML Tennis | B22: BallDontLie ATP adapter | C22: Done | D22: ML | E22: 46235 | F22: 46235 | G22: ALL-STAR tier | R22: =IF($A22<>"",$A22,R21) -> E5 ML Tennis
B23: Collection + train (17.7k examples) | C23: Done | D23: ML | E23: 46235 | F23: 46235 | G23: 63.9% vs 62.2% rank base | R23: =IF($A23<>"",$A23,R22) -> E5 ML Tennis
B24: Fix target leakage (winner as player1) | C24: Done | D24: ML | E24: 46235 | F24: 46235 | G24: Caught pre-launch | R24: =IF($A24<>"",$A24,R23) -> E5 ML Tennis
B25: Retirements, tournament grouping | C25: Done | D25: ML | E25: 46236 | F25: 46236 | G25: VOID badge | R25: =IF($A25<>"",$A25,R24) -> E5 ML Tennis
B26: Kickoff refresh + live derivation | C26: Done | D26: Data | E26: 46237 | F26: 46237 | G26: 26->20 estimated | R26: =IF($A26<>"",$A26,R25) -> E5 ML Tennis
A27: E6 Picks | B27: GET /picks, EV + threshold logic | C27: Done | D27: Backend | E27: 46232 | F27: 46233 | G27: TDD §4.2 | R27: =IF($A27<>"",$A27,R26) -> E6 Picks
B28: Extra markets: DC, O/U goals, corners | C28: Done | D28: Backend | E28: 46234 | F28: 46235 | G28: Poisson-derived | R28: =IF($A28<>"",$A28,R27) -> E6 Picks
B29: Base-rate relative ranking | C29: Done | D29: Backend | E29: 46236 | F29: 46236 | G29: Replaced pure EV | R29: =IF($A29<>"",$A29,R28) -> E6 Picks
B30: GET /history + summary | C30: Done | D30: Backend | E30: 46236 | F30: 46236 | G30: Was a 501 stub | R30: =IF($A30<>"",$A30,R29) -> E6 Picks
A31: E7 Mobile | B31: Expo scaffold, 8 routes, API client | C31: Done | D31: Mobile | E31: 46233 | F31: 46234 | G31: Web + Android verified | R31: =IF($A31<>"",$A31,R30) -> E7 Mobile
B32: Auth, guest sessions, biometrics | C32: Done | D32: Mobile | E32: 46234 | F32: 46234 | G32: SecureStore JWT | R32: =IF($A32<>"",$A32,R31) -> E7 Mobile
B33: Fixture cards, verdicts, flags | C33: Done | D33: Mobile | E33: 46235 | F33: 46236 | G33: Real flag PNGs | R33: =IF($A33<>"",$A33,R32) -> E7 Mobile
B34: Picks UI rebuild (dropdowns, calendar) | C34: Done | D34: Mobile | E34: 46237 | F34: 46237 | G34: Per mockups | R34: =IF($A34<>"",$A34,R33) -> E7 Mobile
B35: Theme: light/dark/system, account-synced | C35: Done | D35: Mobile | E35: 46237 | F35: 46237 | G35: Cross-device verified | R35: =IF($A35<>"",$A35,R34) -> E7 Mobile
B36: Score on each team's row, badge aligned | C36: Done | D36: Mobile | E36: 46238 | F36: 46238 | G36: Per mockups; measured, not eyeballed | R36: =IF($A36<>"",$A36,R35) -> E7 Mobile
B37: Equal control widths, filters aligned | C37: Done | D37: Mobile | E37: 46238 | F37: 46238 | G37: Shared FILTER_TRIGGER_WIDTH | R37: =IF($A37<>"",$A37,R36) -> E7 Mobile
A38: E8 Model Quality | B38: Measure O/U signal (found ~none) | C38: Done | D38: ML | E38: 46236 | F38: 46236 | G38: corr +0.030 | R38: =IF($A38<>"",$A38,R37) -> E8 Model Quality
B39: Refute Negative Binomial premise | C39: Done | D39: ML | E39: 46236 | F39: 46236 | G39: var/mean = 1.003 | R39: =IF($A39<>"",$A39,R38) -> E8 Model Quality
B40: TheStatsAPI eval + xG integration | C40: Done | D40: ML | E40: 46237 | F40: 46237 | G40: xG r=+0.129 vs goals +0.062 | R40: =IF($A40<>"",$A40,R39) -> E8 Model Quality
B41: xG collection (5 leagues) | C41: Done | D41: ML | E41: 46237 | F41: 46238 | G41: Superseded by row 47: 5-league collection finished, 5.9k matches | R41: =IF($A41<>"",$A41,R40) -> E8 Model Quality
...

Sheet Architecture
A1: SportIQ — End-to-End Architecture
A2: Data flows top to bottom. Green = live and working Amber = works with a real gap Red = stubbed or blocked. Offline training track shown separately at the foot.
A4: 1 · EXTERNAL DATA PROVIDERS
A5: Vendors | B5: API-Football (Ultra) fixtures • team stats • injuries H2H • lineups • corners ENDS 2026-09-29 | E5: TheRundown odds: NBA + 5 EU + MLS HEALTHY 5,000/mon | H5: BallDontLie NBA stats · ATP tennis WTA 401 — unsubscribed | K5: TheStatsAPI xG · shotmaps · shots collection in progress | N5: RotoWire NBA injuries NO KEY PROVISIONED | Q5: SportsDataIO / Highlightly Phase 2 US sports · video NOT INTEGRATED
B6: ▼
A7: 2 · ADAPTER LAYER — every provider call goes through here, never direct from a worker
A8: Abstraction | B8: DataSourceAdapter (ABC) fetch_fixtures · fetch_odds fetch_team_stats · fetch_injuries | K8: AdapterFactory routes by sport slug per-adapter error isolation
B9: ▼
A10: 3 · INGESTION & INFERENCE WORKERS (Celery + beat, Redis broker)
A11: Scheduled jobs | B11: ingest_fixtures daily 02:00 UTC ±7 days · features · Elo | E11: ingest_odds every 6h · 3-day window only dates with fixtures | H11: ingest_live_scores every 5 min scores · status · settlement | K11: ingest_injuries every 30 min per-sport isolation (fixed) | N11: run_predictions on new fixture + injury re-inference | Q11: backfill_predictions retrodiction leakage-safe game log
B12: ▼
A13: 4 · STORAGE
A14: Persistence | B14: PostgreSQL 16 fixtures · teams · odds · predictions outcomes · users · team_features | H14: Redis 7 pick cache · guest sessions (24h) Celery broker | N14: models_registry active model per sport promotion = DB update | Q14: ml/artifacts joblib model files (absolute path — deploy risk)
B15: ▲ features read ▼ predictions written
A16: 5 · ML / INFERENCE
A17: Serving | B17: Feature assembly football (18) • nba (16) • tennis (14) train/serve parity enforced | H17: FootballModel Poisson xG ×2 → XGB 1X2 + corners regressors | K17: NBAModel / TennisModel XGB binary + isotonic 2-outcome, no draw | N17: markets.py double chance · O/U goals O/U corners (Poisson) | Q17: Calibration isotonic per class + xG rate calibrators
B18: ▼
A19: 6 · API — FastAPI + Uvicorn
A20: REST | B20: /fixtures · /picks best pick across 4 markets min_probability · min_odds | H20: /history · /stats/model settled performance vs training metrics | N20: /auth · /guest · /user Argon2id · JWT + refresh guest → account migration
B21: ▼
A22: 7 · MOBILE CLIENT — Expo / React Native (the only client)
A23: App | B23: Picks tab day navigator · sport / status filters · league grouping | H23: Live tab in-play fixtures | K23: Profile prefs · theme · push · biometrics | N23: Fixture detail probability bar · H2H panel other markets | Q23: Push notifications code real • EAS project linked no EXPO_ACCESS_TOKEN yet
A26: OFFLINE TRAINING TRACK — run locally, never from a production worker
A27: Pipeline | B27: collect_*_data.py API-Football · BallDontLie nba_api (local only) | E27: collect_thestatsapi_xg.py xG + cross-provider join date+score, name tiebreak | H27: ml/data/*.parquet game logs · lineups corners · xG | K27: train_*.py Optuna → calibration → joblib artefact | N27: MLflow runs · metrics local store | Q27: models_registry row is_active flip promotes no redeploy needed
A30: ARCHITECTURAL NOTES
A31: • Sport-agnostic by design — every core table is keyed by sport_id; adding a sport is a config/data insert, not a schema change.
A32: • Model promotion is a DB update (models_registry.is_active), never a redeploy — TDD §3.1.
A33: • Train/serve parity is enforced in one module per sport: assemble_from_game_log and assemble_from_live_db must stay in lock-step.
A34: • Historical (box-score) key-player logic is kept OUT of app/models_ml/ so it can never be imported into the live path — target-leakage guard.
A35: • Per-item error isolation is now the default in every provider loop: one league or sport failing must not abort the rest.
A36: • nba_api is offline-only — stats.nba.com blocks all cloud IPs, so it must never run from a production worker.
A37: ⚠ DEPLOYMENT GAP: nothing is deployed. No infra/, artefact paths are absolute Windows paths, no monitoring, no EAS build.
A39: Legend | B39: Live & working | E39: Real gap | H39: Stubbed / blocked | K39: Datastore | N39: ML | Q39: API / App
A41: 8 • RUNTIME • Render (production, live 13 Aug 2026)
A42: Deployed | B42: sportpiq-api (web) gunicorn • binds $PORT alembic in preDeployCommand | H42: sportpiq-worker Celery prefork executes every task | K42: sportpiq-beat EXACTLY ONE, ever two would double-spend quota | N42: sportpiq-db (PG16) sportpiq-redis managed, private network | Q42: Models baked into the image stage_artefacts + manifest seed_model_registry on a new DB
A43: Local celery must stay OFF while production runs: both hit the same metered providers, and TheRundown is 5,000 per MONTH. Promotion is no longer a DB flip -- retrain, stage, commit, redeploy, seed.

Sheet Epic Summary
A1: Epic Summary
A3: Epic | B3: Total | C3: Done | D3: In progress / Planned | E3: Blocked | F3: % Complete
A4: E1 Foundation | B4: =C4+D4+E4 -> 4 | C4: =COUNTIFS('Delivery Board'!$R$5:$R$500,$A4,'Delivery Board'!$C$5:$C$500,"Done") -> 4 | D4: =COUNTIFS('Delivery Board'!$R$5:$R$500,$A4,'Delivery Board'!$C$5:$C$500,"Planned")+COUNTIFS('Delivery Board'!$R$5:$R$500,$A4,'Delivery Board'!$C$5:$C$500,"In progress")+COUNTIFS('Delivery Board'!$R$5:$R$500,$A4,'Delivery Board'!$C$5:$C$500,"Milestone") -> 0 | E4: =COUNTIFS('Delivery Board'!$R$5:$R$500,$A4,'Delivery Board'!$C$5:$C$500,"Blocked") -> 0 | F4: =IF(B4=0,0,C4/B4) -> 1
A5: E2 Ingestion | B5: =C5+D5+E5 -> 14 | C5: =COUNTIFS('Delivery Board'!$R$5:$R$500,$A5,'Delivery Board'!$C$5:$C$500,"Done") -> 13 | D5: =COUNTIFS('Delivery Board'!$R$5:$R$500,$A5,'Delivery Board'!$C$5:$C$500,"Planned")+COUNTIFS('Delivery Board'!$R$5:$R$500,$A5,'Delivery Board'!$C$5:$C$500,"In progress")+COUNTIFS('Delivery Board'!$R$5:$R$500,$A5,'Delivery Board'!$C$5:$C$500,"Milestone") -> 1 | E5: =COUNTIFS('Delivery Board'!$R$5:$R$500,$A5,'Delivery Board'!$C$5:$C$500,"Blocked") -> 0 | F5: =IF(B5=0,0,C5/B5) -> 0.92857143
A6: E3 ML NBA | B6: =C6+D6+E6 -> 5 | C6: =COUNTIFS('Delivery Board'!$R$5:$R$500,$A6,'Delivery Board'!$C$5:$C$500,"Done") -> 5 | D6: =COUNTIFS('Delivery Board'!$R$5:$R$500,$A6,'Delivery Board'!$C$5:$C$500,"Planned")+COUNTIFS('Delivery Board'!$R$5:$R$500,$A6,'Delivery Board'!$C$5:$C$500,"In progress")+COUNTIFS('Delivery Board'!$R$5:$R$500,$A6,'Delivery Board'!$C$5:$C$500,"Milestone") -> 0 | E6: =COUNTIFS('Delivery Board'!$R$5:$R$500,$A6,'Delivery Board'!$C$5:$C$500,"Blocked") -> 0 | F6: =IF(B6=0,0,C6/B6) -> 1
A7: E4 ML Football | B7: =C7+D7+E7 -> 10 | C7: =COUNTIFS('Delivery Board'!$R$5:$R$500,$A7,'Delivery Board'!$C$5:$C$500,"Done") -> 9 | D7: =COUNTIFS('Delivery Board'!$R$5:$R$500,$A7,'Delivery Board'!$C$5:$C$500,"Planned")+COUNTIFS('Delivery Board'!$R$5:$R$500,$A7,'Delivery Board'!$C$5:$C$500,"In progress")+COUNTIFS('Delivery Board'!$R$5:$R$500,$A7,'Delivery Board'!$C$5:$C$500,"Milestone") -> 1 | E7: =COUNTIFS('Delivery Board'!$R$5:$R$500,$A7,'Delivery Board'!$C$5:$C$500,"Blocked") -> 0 | F7: =IF(B7=0,0,C7/B7) -> 0.9
A8: E5 ML Tennis | B8: =C8+D8+E8 -> 24 | C8: =COUNTIFS('Delivery Board'!$R$5:$R$500,$A8,'Delivery Board'!$C$5:$C$500,"Done") -> 24 | D8: =COUNTIFS('Delivery Board'!$R$5:$R$500,$A8,'Delivery Board'!$C$5:$C$500,"Planned")+COUNTIFS('Delivery Board'!$R$5:$R$500,$A8,'Delivery Board'!$C$5:$C$500,"In progress")+COUNTIFS('Delivery Board'!$R$5:$R$500,$A8,'Delivery Board'!$C$5:$C$500,"Milestone") -> 0 | E8: =COUNTIFS('Delivery Board'!$R$5:$R$500,$A8,'Delivery Board'!$C$5:$C$500,"Blocked") -> 0 | F8: =IF(B8=0,0,C8/B8) -> 1
A9: E6 Picks | B9: =C9+D9+E9 -> 18 | C9: =COUNTIFS('Delivery Board'!$R$5:$R$500,$A9,'Delivery Board'!$C$5:$C$500,"Done") -> 16 | D9: =COUNTIFS('Delivery Board'!$R$5:$R$500,$A9,'Delivery Board'!$C$5:$C$500,"Planned")+COUNTIFS('Delivery Board'!$R$5:$R$500,$A9,'Delivery Board'!$C$5:$C$500,"In progress")+COUNTIFS('Delivery Board'!$R$5:$R$500,$A9,'Delivery Board'!$C$5:$C$500,"Milestone") -> 2 | E9: =COUNTIFS('Delivery Board'!$R$5:$R$500,$A9,'Delivery Board'!$C$5:$C$500,"Blocked") -> 0 | F9: =IF(B9=0,0,C9/B9) -> 0.88888889
A10: E7 Mobile | B10: =C10+D10+E10 -> 32 | C10: =COUNTIFS('Delivery Board'!$R$5:$R$500,$A10,'Delivery Board'!$C$5:$C$500,"Done") -> 28 | D10: =COUNTIFS('Delivery Board'!$R$5:$R$500,$A10,'Delivery Board'!$C$5:$C$500,"Planned")+COUNTIFS('Delivery Board'!$R$5:$R$500,$A10,'Delivery Board'!$C$5:$C$500,"In progress")+COUNTIFS('Delivery Board'!$R$5:$R$500,$A10,'Delivery Board'!$C$5:$C$500,"Milestone") -> 4 | E10: =COUNTIFS('Delivery Board'!$R$5:$R$500,$A10,'Delivery Board'!$C$5:$C$500,"Blocked") -> 0 | F10: =IF(B10=0,0,C10/B10) -> 0.875
A11: E8 Model Quality | B11: =C11+D11+E11 -> 65 | C11: =COUNTIFS('Delivery Board'!$R$5:$R$500,$A11,'Delivery Board'!$C$5:$C$500,"Done") -> 61 | D11: =COUNTIFS('Delivery Board'!$R$5:$R$500,$A11,'Delivery Board'!$C$5:$C$500,"Planned")+COUNTIFS('Delivery Board'!$R$5:$R$500,$A11,'Delivery Board'!$C$5:$C$500,"In progress")+COUNTIFS('Delivery Board'!$R$5:$R$500,$A11,'Delivery Board'!$C$5:$C$500,"Milestone") -> 4 | E11: =COUNTIFS('Delivery Board'!$R$5:$R$500,$A11,'Delivery Board'!$C$5:$C$500,"Blocked") -> 0 | F11: =IF(B11=0,0,C11/B11) -> 0.93846154
A12: E9 Data Ops | B12: =C12+D12+E12 -> 47 | C12: =COUNTIFS('Delivery Board'!$R$5:$R$500,$A12,'Delivery Board'!$C$5:$C$500,"Done") -> 37 | D12: =COUNTIFS('Delivery Board'!$R$5:$R$500,$A12,'Delivery Board'!$C$5:$C$500,"Planned")+COUNTIFS('Delivery Board'!$R$5:$R$500,$A12,'Delivery Board'!$C$5:$C$500,"In progress")+COUNTIFS('Delivery Board'!$R$5:$R$500,$A12,'Delivery Board'!$C$5:$C$500,"Milestone") -> 9 | E12: =COUNTIFS('Delivery Board'!$R$5:$R$500,$A12,'Delivery Board'!$C$5:$C$500,"Blocked") -> 1 | F12: =IF(B12=0,0,C12/B12) -> 0.78723404
A13: E10 Deploy | B13: =C13+D13+E13 -> 36 | C13: =COUNTIFS('Delivery Board'!$R$5:$R$500,$A13,'Delivery Board'!$C$5:$C$500,"Done") -> 33 | D13: =COUNTIFS('Delivery Board'!$R$5:$R$500,$A13,'Delivery Board'!$C$5:$C$500,"Planned")+COUNTIFS('Delivery Board'!$R$5:$R$500,$A13,'Delivery Board'!$C$5:$C$500,"In progress")+COUNTIFS('Delivery Board'!$R$5:$R$500,$A13,'Delivery Board'!$C$5:$C$500,"Milestone") -> 3 | E13: =COUNTIFS('Delivery Board'!$R$5:$R$500,$A13,'Delivery Board'!$C$5:$C$500,"Blocked") -> 0 | F13: =IF(B13=0,0,C13/B13) -> 0.91666667
A14: E11 Ops Resilience | B14: =C14+D14+E14 -> 32 | C14: =COUNTIFS('Delivery Board'!$R$5:$R$500,$A14,'Delivery Board'!$C$5:$C$500,"Done") -> 28 | D14: =COUNTIFS('Delivery Board'!$R$5:$R$500,$A14,'Delivery Board'!$C$5:$C$500,"Planned")+COUNTIFS('Delivery Board'!$R$5:$R$500,$A14,'Delivery Board'!$C$5:$C$500,"In progress")+COUNTIFS('Delivery Board'!$R$5:$R$500,$A14,'Delivery Board'!$C$5:$C$500,"Milestone") -> 4 | E14: =COUNTIFS('Delivery Board'!$R$5:$R$500,$A14,'Delivery Board'!$C$5:$C$500,"Blocked") -> 0 | F14: =IF(B14=0,0,C14/B14) -> 0.875
A16: OVERALL | B16: =SUM(B4:B14) -> 287 | C16: =SUM(C4:C14) -> 258 | D16: =SUM(D4:D14) -> 28 | E16: =SUM(E4:E14) -> 1 | F16: =IF(B16=0,0,C16/B16) -> 0.8989547
A18: Unassigned (should be 0) | B18: =COUNTIFS('Delivery Board'!$R$5:$R$500,"<>",'Delivery Board'!$C$5:$C$500,"Done")+COUNTIFS('Delivery Board'!$R$5:$R$500,"<>",'Delivery Board'!$C$5:$C$500,"Planned")+COUNTIFS('Delivery Board'!$R$5:$R$500,"<>",'Delivery Board'!$C$5:$C$500,"In progress")+COUNTIFS('Delivery Board'!$R$5:$R$500,"<>",'Delivery Board'!$C$5:$C$500,"Milestone")+COUNTIFS('Delivery Board'!$R$5:$R$500,"<>",'Delivery Board'!$C$5:$C$500,"Blocked")-B16 -> 0
A19: Auto-calculated from the Delivery Board. Add an epic here if 'Unassigned' is ever non-zero.

Sheet Risks & Decisions
A1: Risks, Blockers & Open Decisions
A3: Item | B3: Type | C3: Impact | D3: Status | E3: Action / Owner decision
A4: Model edge is unproven | B4: Risk | C4: Critical | D4: Open | E4: 1X2 +1.9pp over baseline; O/U ~base-rate. Retrain with xG is the decision point.
A5: Over/Under surfaced most, has least signal | B5: Risk | C5: High | D5: Open | E5: GO/NO-GO 2026-08-10 — surface fewer markets rather than ship confident-looking noise.
A6: Not deployed anywhere | B6: Blocker | C6: Critical | D6: Planned | E6: No infra/, absolute Windows artefact path. ~2-4 weeks of work.
A7: No monitoring — silent failures | B7: Risk | C7: High | D7: Planned | E7: Injury worker failed for weeks unnoticed; Docker down looked like an app bug.
A8: TheRundown quota exhausted | B8: Blocker | C8: Medium | D8: Decision | E8: Pro $99.99/mo before EPL opens 21 Aug, or narrow + stay on Basic.
A9: API-Football is a single point of failure | B9: Risk | C9: High | D9: Accepted | E9: Fixtures, stats, injuries, H2H, lineups all from one vendor. Auto-renews.
A10: European odds may need no vendor at all | B10: Opportunity | C10: Medium | D10: Open | E10: Re-test coverage.odds on 21 Aug; could make TheRundown NBA-only.
A11: No EAS project | B11: Blocker | C11: High | D11: Planned | E11: Cannot ship the app to a single user, nor mint push tokens.
A12: WTA blocked on subscription | B12: Blocker | C12: Low | D12: Deferred | E12: Code written and unit-tested; needs that tour subscribed.
A13: NBA injuries dead (no RotoWire key) | B13: Blocker | C13: Medium | D13: Deferred | E13: player_injury_status stays empty; NBA key-player features never vary.
A14: Mobile has no Jest/ESLint | B14: Risk | C14: Medium | D14: Planned | E14: tsc is the only automated mobile check.
... A119: Estimated-kickoff fixtures are now live-computed for a day longer | B119: Risk | C119: Low | D119: Monitored | E119: The cost of the fix, stated rather than buried: an estimated-kickoff fixture is no longer frozen until its placeholder day ends, so its card can move during that window -- the mutability the freeze exists to prevent. Right side to err on when the alternative is a card frozen permanently blank, but watch for a tennis card visibly changing within its match day.

Sheet Edge Measurement
A1: SportIQ — Edge Measurement Plan (P0-P3)
A2: Tracks whether the predictions actually work, which the Delivery Board deliberately does not: that tracks what was BUILT. As of 2026-08-10 there is no demonstrated betting edge — football ROI -6.4% (n=38), CLV -3.58% (n=27, market moving away from our picks), tennis +1.6pp over 'always back the higher-ranked player'. Green CI is not evidence the predictions are good.
A4: Priority | B4: Item | C4: Status | D4: Depends on | E4: Why it matters / what it answers
A5: P0 | B5: Separate real pre-game forecasts from retrodictions | C5: Done | D5: — | E5: DONE (7a611e9). predictions.kind = pre_match | retrodiction | unknown, set at write time by each path, never inferred. Timestamps could NOT substitute: regenerating 91 football predictions earlier that day reset created_at to after those kickoffs. The backfill is therefore one-directional — created_at < kickoff proves a forecast, the reverse proves nothing, so those rows are UNKNOWN rather than guessed. UNKNOWN is also the column default, so a future path that forgets to set it is excluded from skill measurement rather than silently claiming to be a forecast. Result: football 283 pre_match / 90 unknown, tennis 146 / 453.
A6: P0 | B6: Confirm capture_closing_odds is actually writing | C6: Done | D6: — | E6: DONE — and it was already working. 19 task runs this session and 1,151 odds rows stamped within 45 min of kickoff, against the n=27 the -3.58% CLV figure rests on. So CLV was computed on a stale slice, not a thin one: this is a READ problem, not a capture problem, and needs analysis rather than a build.
A7: P1 | B7: Spec what /history reports, before building it | C7: Done | D7: P0 | E7: DONE — docs/history-metrics-spec.md, written before the endpoint exists so its shape cannot be chosen after seeing which cut looks best. Defines population (pre_match only, voids excluded, unknown counted not hidden), exact metric definitions, multiple-comparisons discipline, and a hard requirement that every metric carries n, a CI and its detectable effect. Also lists what would make the endpoint MISLEADING, so it can be checked against.
A8: P1 | B8: Build GET /history over existing settled outcomes | C8: Done | D8: P0, spec | E8: DONE (53b7d2a) — and it was never a 501 stub; CLAUDE.md was stale. The endpoint has been LIVE and serving a contaminated number: /history/summary averaged both prediction paths, which measured football at 53.3% instead of 56.1% and tennis 61.7% instead of 63.6%. DOWNWARD, the opposite of the predicted direction — retrodictions score worse, not better, because assemble_from_game_log has a leakage guard and thinner features. Now pre_match by default, retrodictions behind an explicit ?kind=, excluded rows counted rather than dropped.
A9: P1 | B9: Grade the pick that was SHOWN, not a recomputed one | C9: Done | D9: P0 | E9: Resolved by pick_snapshots: /history will grade the stored snapshot rather than recomputing, so it measures the product users actually saw. Applies only to fixtures captured from 2026-08-10 onward.
A10: P2 | B10: PRE-REGISTER the verdict thresholds (SETTLED 2026-08-11, spec §9): CLV primary over accuracy on sample size (n~223-396 vs ~1,650); edge = CI excluding 0; the no-edge response pre-committed; re-read 2026-09-15 | C10: Done | D10: spec | E10: What counts as an edge, what counts as none, and what happens in each case - written before looking at results. Same discipline that made the Tier-1 and key-player calls trustworthy rather than fitted.
A11: P2 | B11: MIN_REPORTABLE_N 30 -> 93 to match the spec: the smallest n whose 95% Wilson interval is under 20 points. Excludes tennis (n=77), admits football (n=139) — set by the rule, not to fit the data | C11: Done | D11: pre-registration
A12: P2 | B12: sufficient_sample split into sufficient_sample (safe to display) + conclusive (safe to act on). One flag read as "trustworthy" when it only meant "big enough to print" | C12: Done | D12: pre-registration
A13: P2 | B13: First honest read: per sport, per market, per league | C13: Done | D13: /history | E13: DONE 13 Aug. Per-league existed for 1X2 only and per-market pooled only; per_league_market_metrics now reports both cuts crossed. Goals under-3.5 Brier spans 0.168 (J1) to 0.261 (Veikkausliiga) against a pooled 0.2096.
A14: P2 | B14: Re-read CLV at a real sample size | C14: Done | D14: P0 capture check | E14: DONE — and the CONTROL changed the reading. Favoured side -3.47% vs the side NOT favoured +0.83%, a -4.30pp gap (n=81 each). But football's control is ALSO negative (-2.40%), so a real part of the raw -3.61% is systematic price drift rather than the model. The control is not clean either: for a 3-way market it is the less-likely of home/away, usually the underdog, whose prices are longer and more volatile. Directional evidence against an edge; NOT a number to quote precisely. The naive -4.00% headline would have overstated it.
A15: P2 | B15: Do confidence tiers mean anything? | C15: Done | D15: /history | E15: ANSWERED: no, and worse than no. HIGH claims 74.1% delivers 60.9% (n=69); MEDIUM claims 57.8% delivers 68.5% (n=89) — the badge pointed users at the WEAKER set. Intervals overlap so the inversion is not established; the calibration gap is. Badge hidden from mobile (7233029), field still stored as measurement data. The push gate still fires on HIGH and is knowingly left in place — n=69 is too thin to rewrite it on, and exactly one real token exists — but it MUST be resolved before push reaches real users.
A16: P2 | B16: Re-run completeness-vs-correctness | C16: Done | D16: /history | E16: DONE: <0.25 33.3% (n=9), 0.25-0.35 37.5% (n=16), >=0.35 69.9% (n=123). The floor works, but the real break is at 0.35 — where mobile's own LOW_CONFIDENCE_COMPLETENESS already sits. The 0.25 choice was defensible on the extremeness evidence used at the time (85% of picks below it were >=0.90 confident vs 6% above); correctness points higher. NOT changed: n=16 in the middle band, and the decision belongs with the pre-registration rather than to whoever is looking at the data.
A17: P3 | B17: Decide Over/Under's future on the evidence — DONE 2026-08-11, and it split in two: goals_total n=242 r=+0.049 (0.2% of variance) is barred from winning the headline pick; corners_total n=234 r=+0.288 (8.3%, ~4.4 SE from zero) is KEPT. Decidable without the CLV read | C17: Done | D17: P2 read | E17: Already measured as near-base-rate (predicted xG vs actual goals r=+0.030). The open question is not how to improve it but whether to keep surfacing it as a confident pick.
A18: P3 | B18: Let the measurement inform the 22 Sep renewal | C18: Milestone | D18: P2 read | E18: API-Football ends 2026-09-29. Renewing to collect more history is a different decision from renewing to serve a working product.
A19: HOLD | B19: No new leagues until measurement lands | C19: Hold | D19: — | E19: Nine were added this week. More widens coverage of something whose value is unproven.
A20: HOLD | B20: No new markets until measurement lands | C20: Hold | D20: — | E20: Corners and O/U are already surfaced without evidence they are worth backing.
A21: HOLD | B21: No retrains chasing accuracy | C21: Hold | D21: — | E21: Three retrains in two days moved the headline by noise. The binding constraint is signal and evidence, not tuning.
A23: P0 | B23: FINDING: the sample cannot yet answer the question | C23: Done | D23: power analysis | E23: Measured after closing P0. At 80% power, n=139 football detects only a 10.5pp edge and we believe ours is 4.1pp — 891 graded pre-match picks needed, 6x what exists. Tennis is far worse: 1.6pp believed edge needs ~5,406, against 79 (68x). CONSEQUENCE: the first /history read cannot conclude anything about edge. Build it as instrumentation that accumulates, and expect a real verdict in months, not days. Anyone reading an early number as proof either way is reading noise.
A24: P1 | B24: Set expectations: /history is instrumentation, not a verdict | C24: Done | D24: the finding above | E24: DONE. Every accuracy now carries n, a 95% Wilson interval and its minimum detectable effect. Live: football n=139 acc 0.561 CI [0.478,0.641] detectable 0.105; tennis n=77 acc 0.636 CI [0.525,0.735] detectable 0.136. The intervals are the point — football's spans 16 points and its detectable effect dwarfs the 4.1pp edge we believe in, so the number cannot settle the question either way.
A25: P1 | B25: FINDING: the pick we SHOW is never persisted | C25: Done | D25: spec §2b | E25: RESOLVED by pick_snapshots (8f794e0). Product-skill metrics accumulate from 2026-08-10; nothing before it is recoverable.
... A27: P2 | B27: Push gate no longer uses the confidence tier | C27: Done | D27: pre-registration | E27: DONE (6bd3582). Replaced with the FEED'S OWN selection (_bulk_best_picks), not a new threshold — n=69 was far too thin to invent one, and doing so was explicitly refused for the completeness floor on n=16. A push can now only be sent for a pick the app itself would surface. Removing the gate outright was not an option: best_outcome returns something for almost any priced fixture. Also fixed a real incoherence found while reading the flow — the old path used h2h-only best_outcome while the card shows the best pick ACROSS markets, so a push could say 'back home' while the app showed 'UNDER 3.5' for the same fixture.
A28: P0 | B28: FINDING: the snapshot pipeline was never running. Worker and beat launched 3h BEFORE snapshot_picks.py was written, so the running beat had no snapshot entry — one row (a manual test call) in 24h. Third instance of the stale-process trap; restarted and verified through the real broker | C28: Done | D28: pick snapshots
A29: P2 | B29: VALIDATED §9.7: 79% of upcoming fixtures yield a pick; 34% of settled ones carry odds, so ~53 CLV-eligible/week reaches n=223 in 4-5 weeks. The 2026-09-15 re-read date holds and is slightly conservative | C29: Done | D29: pre-registration
A30: P2 | B30: FINDING: odds coverage is fixture-binary and the whole gap was the 9 Tier-1 leagues (7 at ZERO). NOT a bug — added 08-09 with historically-backfilled fixtures that never passed a live odds window. All 9 report coverage.odds=true and 8 returned real prices on demand | C30: Done | D30: CLV sample size
A31: P1 | B31: Beat now publishes its own code fingerprint (beat_init) and check_stale reports it. The blind spot was exactly where the damage was: only the worker published, so a stale SCHEDULER read as "ok". Both processes moved onto dev_worker.py, which restarts on change | C31: Done | D31: the snapshot finding
A32: P1 | B32: Guard: every scheduled task must belong to a module the worker imports, and the snapshot entry is pinned by name — the whole pre-registration rests on one beat_schedule line whose absence is silent | C32: Done | D32: beat liveness
A33: P1 | B33: Sentry wired into the Celery worker and beat, not just the API — it had only ever been initialised in create_app(), so every silent worker failure this project has had was unreportable. One shared initialiser; events tagged with component + loaded code fingerprint | C33: Done | D33: the snapshot finding
A34: P1 | B34: monitor_beat_tasks makes each beat_schedule entry a Sentry cron monitor, so a scheduled task that STOPS ARRIVING alerts. The one failure ordinary error reporting cannot catch: no exception, no failed task, no log line — the work just never happens | C34: Done | D34: Sentry wiring
A35: P2 | B35: SENTRY_DSN_BACKEND now populated in backend/.env (gitignored). The DSN existed in keys.docx from the start — it had simply never reached the environment the app reads. Verified: init_sentry True, test event accepted, transport flushed | C35: Done | D35: user action
A36: P1 | B36: Tennis odds were stale up to 6h: the hourly job used BallDontLie only (4 matches priced) while TheRundown (31 ATP events, all unmasked) arrived only on the shared 6-hourly run. Given its own 2-hourly job — ~720 calls/mo vs ~1,440 hourly, which would not fit alongside football's expected ~3,600. One day went 4 of 28 priced -> 24 of 28 | C36: Done | D36: odds coverage
A37: P2 | B37: NOTE: odds make the feed SMALLER, not larger — that day went 8 fixtures to 4. min_odds can only apply where a price exists, and tennis favourites at ~0.70 price below a 1.50 floor. Those cards previously showed because the filter silently could not apply | C37: Done | D37: odds coverage
A38: P3 | B38: Football empty cards are NOT a fault: ODDS_LOOKAHEAD_DAYS=3 and no football fixture is currently inside 3 days. Recheck once the European seasons open on 21 Aug | C38: Done | D38: odds coverage
A39: P1 | B39: PERSON-name matching for tennis odds: the lookup was exact + case-sensitive, so 4 fixtures with real prices showed empty cards (SoonWoo vs Soonwoo; Wu Yibing vs Yibing Wu; Chak Lam Coleman Wong). Token-SET match needing >=2 shared tokens, opt-in per sport. 24 of 28 -> 28 of 28 priced; model/market agree on the favourite in 21 of 28 | C39: Done | D39: odds coverage
... A55: MODEL | B55: Seed now genuinely load-bearing: the tuned config uses subsample 0.88 / colsample 0.63, so training is stochastic for the first time. Pinning it in #2 before this landed is what keeps runs comparable | C55: Done | D55: #2/#4
A56: MODEL | B56: FOLLOW-UP: the corners Poisson regressors are still untuned (MAE unchanged at 2.156, which confirms the scoping). Same pattern as Layer 1 would apply | C56: Done | D56: #5 | E56: DONE 13 Aug. Tuned against validation Poisson deviance, and the Over/Under CORNERS market got its first held-out evaluation at the same time - it had shipped judged by MAE alone while the product sold P(under 9.5).
A57: MODEL | B57: goals_total re-admission TRIGGER is now CHECKED AUTOMATICALLY, not remembered: app/predictions/market_signal.py holds the pre-registered thresholds (n>=200, r>=+0.15, 95% CI low > +0.05 on SETTLED pre-match predictions from football_xgb_v20260812080921 onward) and a weekly Celery task reports status, logging WARNING + a Sentry message when met | C57: Done | D57: O/U
A58: MODEL | B58: The check deliberately does NOT lift the bar itself — re-admitting a market changes what users are told to back, so that stays a human decision. Pinned by a test that the worker never imports the pick-selection set | C58: Done | D58: O/U
...

Sheet APIs & Quotas
A1: External APIs, Quotas & Expiry
A2: All figures read live from each provider at 2026-08-09. No credentials are stored in this file.
A4: Provider | B4: What we get from it | C4: Plan / tier | D4: Quota | E4: Used (as checked) | F4: Remaining | G4: Expiry / reset | H4: Status | I4: Notes & constraints
A5: API-Football (v3, direct host) | B5: Football fixtures, team stats, injuries, lineups, corners, H2H, and Brasileirao odds. The primary football provider. | C5: Ultra | D5: 75,000 / day (450 / minute) | E5: 23,783 today | F5: 51,217 today | G5: SUBSCRIPTION ENDS 2026-09-29 | H5: HEALTHY | I5: Read live from GET /status on 2026-08-10: plan=Ultra, active=true, end=2026-09-29. CORRECTION: the sheet previously said Pro / 7,500 per day / ends 2026-08-29 and called it a 20-day hard deadline - the real end date is a month later. The 450/minute cap is the one that actually bites: a bulk collection run saturates it and then every OTHER caller gets HTTP 200 with an empty response and results=0, which reads exactly like 'this league has no data'. Do not run a live probe against a background collection.
A6: TheRundown (via RapidAPI) | B6: Odds: NBA, the 5 European football leagues, MLS, and ATP/WTA tennis. Only real source of game-totals lines. | C6: Pro | D6: 5,000 / month | E6: 68 this period | F6: 4,932 | G6: resets in ~27 days | H6: HEALTHY | I6: Upgraded from 1,000/month. Odds job stays at 6h: worst case at 3h is 134% of quota. No Brazil, Scotland or China coverage at all. Only 3 of ~15 affiliates return real prices; the rest send a 0.0001 masked sentinel.
A7: BallDontLie - ATP tennis | B7: Tennis fixtures, matches, match_stats (serve/return), odds (DraftKings + FanDuel), rankings, H2H. | C7: GOAT | D7: 600 / minute | E7: 1 (probe) | F7: 599 | G7: no expiry observed | H7: HEALTHY | I7: 10x the ALL-STAR limit. /match_stats paginates by SEASON not per fixture, so bulk history is minutes not days. NOTE: season and match_ids filters are SILENTLY IGNORED on some endpoints - always test with a nonsense value.
A8: BallDontLie - WTA tennis | B8: Nothing usable. /rankings only. | C8: Free (not subscribed) | D8: 5 / minute | E8: n/a | F8: n/a | G8: n/a | H8: BLOCKED | I8: Every endpoint except /rankings returns 401. GOAT covers ATP ONLY - WTA needs its own subscription. Code is written and unit-tested; just point league='wta' once subscribed.
A9: BallDontLie - NBA | B9: NBA fixtures and team stats for live serving. | C9: Free | D9: 5 / minute | E9: 1 (probe) | F9: 4 | G9: no expiry | H9: TIGHT | I9: /season_averages, /standings and /player_injuries all 401 on this tier. 5/min is why ingest caches per-run; fine for 30 teams, would not scale.
A10: TheStatsAPI | B10: Expected goals (xG) for football - the only xG source; API-Football supplies none at any tier. | C10: paid | D10: 120 / minute (+ a monthly cap) | E10: 0 (probe) | F10: 120 this minute | G10: monthly cap not exposed in headers | H10: WATCH | I10: Monthly quota is real and has been hit before - it reports as 'season not found', which is misleading. Per-minute limit was raised 12 -> 120; the collector now reads pacing from x-ratelimit-limit rather than a constant.
A11: nba_api (stats.nba.com) | B11: NBA historical training data only. | C11: free | D11: unthrottled | E11: n/a | F11: n/a | G11: none | H11: LOCAL ONLY | I11: Blocks ALL cloud-provider IPs at the network level. Must never be called from a production worker - offline training only.
A12: Expo Push API | B12: Delivering push notifications to devices. | C12: unauthenticated | D12: lower unauthenticated rate limit | E12: n/a | F12: n/a | G12: none | H12: WORKS | I12: No EXPO_ACCESS_TOKEN provisioned. Sends work and were verified on a real device. Ticket is returned but the RECEIPT is never checked, so delivery failures are currently invisible.
A13: RotoWire | B13: NBA injuries (intended). | C13: never provisioned | D13: n/a | E13: n/a | F13: n/a | G13: n/a | H13: NOT PROVISIONED | I13: No key was ever obtained. Adapter is a stub, so NBA player_injury_status stays empty. Football injuries come from API-Football and are real.
A14: SportsDataIO | B14: Phase 2 US sports (NFL/NHL/MLB). | C14: never provisioned | D14: n/a | E14: n/a | F14: n/a | G14: n/a | H14: NOT PROVISIONED | I14: Adapter is a stub. Not needed until Phase 2.
A16: Re-check by calling each provider's own status endpoint; do not trust these figures after the dates above. API-Football: GET /status. TheRundown: x-ratelimit-requests-* response headers. BallDontLie / TheStatsAPI: x-ratelimit-* response headers.
A18: 13 Aug: PRODUCTION IS NOW LIVE AND SHARES EVERY QUOTA ABOVE. The figures here were read from a single local machine. Render's beat is now the only scheduler that should be running - local celery was stopped the same day, because two schedulers against the same providers double-spend metered quota and TheRundown is 5,000 per MONTH.
A20: 13 Aug: BallDontLie /wnba/v1 confirmed live on the SAME key as NBA -- 200, mid-season, history past 2024. /season_averages is a 404 and /standings + /player_injuries 401, so WNBA carries no player-level data at all. TheRundown covers WNBA at sport_id 8.
